Workbook

Sheet Mô hình Scrum
A1: SmartMaint (FA26SE147) — Mô hình Scrum giai đoạn code
A2: Phạm vi: toàn bộ Product Backlog của dự án (Web + Backend + Mobile + AI), bắt đầu từ Sprint 1 = Code Frame. Lập ngày 30/09/2026.
A4: 1. Vai trò Scrum
A5: Vai trò | B5: Trách nhiệm | C5: Người đảm nhận
A6: Product Owner | B6: Quản lý và sắp thứ tự Product Backlog; quyết định module nào vào sprint; chấp nhận hoặc trả lại increment cuối sprint.
A7: Scrum Master | B7: Giữ nhịp các sự kiện Scrum; gỡ vướng cho nhóm; nhắc cập nhật trạng thái trên sheet và Trello.
A8: Development Team | B8: Làm các module (Backend, Web, Mobile), tự test, review chéo qua Pull Request.
A9: Ô vàng = để trống, phân vai sau (theo yêu cầu Leader).
A11: 2. Sự kiện Scrum (sprint 2 tuần)
A12: Sự kiện | B12: Khi nào | C12: Làm gì | D12: Đầu ra
A13: Sprint Planning | B13: Buổi họp thứ Ba đầu mỗi sprint: 29/09, 13/10, 27/10, 10/11, 24/11/2026. | C13: Chọn module của sprint từ Product Backlog, xác nhận phụ thuộc, giao người làm. | D13: Cột Sprint + Owner trong sheet Product Backlog.
A14: Họp đồng bộ (thay Daily Scrum) | B14: Thứ Ba + thứ Sáu hằng tuần (lịch họp cố định của nhóm). | C14: Mỗi người: đã làm gì, sẽ làm gì, đang vướng gì. | D14: Cột Trạng thái được cập nhật; việc vướng ghi vào sheet Issues của Project Tracking.
A15: Backlog Refinement | B15: Thứ Sáu tuần đầu của mỗi sprint. | C15: Làm rõ các module của sprint kế tiếp, điều chỉnh phụ thuộc và man-day. | D15: Product Backlog sẵn sàng cho Sprint Planning sau.
A16: Sprint Review | B16: Cuối sprint, trùng mốc nộp của trường: 12/10, 26/10, 09/11, 23/11, 07/12/2026. | C16: Demo increment với GVHD, nhận góp ý. | D16: Góp ý ghi vào sheet Q&A / Issues; tag release trên GitHub.
A17: Sprint Retrospective | B17: Ngay sau Sprint Review. | C17: Điều gì làm tốt, điều gì chưa tốt, chọn 1–2 cải tiến. | D17: Ghi chú cải tiến áp dụng cho sprint sau.
A19: 3. Artifact
A20: Artifact | B20: Ở đâu | C20: Ghi chú
A21: Product Backlog | B21: Sheet 'Product Backlog' (71 module, sắp theo thứ tự làm). | C21: Mỗi module = 1 function trong R3 (mục 3.2–3.18) hoặc 1 hạng mục kỹ thuật / Mobile từ R2.
A22: Sprint Backlog | B22: Lọc cột Sprint trong sheet 'Product Backlog'. | C22: Tiến độ từng sprint tự tính ở sheet 'Sprint'.
A23: Increment | B23: Bản build trên Railway + Vercel (Web) và bản build Mobile. | C23: Gắn tag release ở mỗi mốc nộp (R2 mục 6.2).
A25: 4. Definition of Done (một module được tính "Hoàn thành" khi)
A26: DoD-1 | B26: Code đã merge vào main qua Pull Request, có ít nhất 1 người review (R2 mục 6.2).
A27: DoD-2 | B27: Đúng Function Details và Business Rules trong R3, đúng bảng quyền Screen Authorization (R3 mục 3.1.3).
A28: DoD-3 | B28: Logic workflow Case có unit test (mục tiêu ≥ 70% — R2 mục 1.2); API có test tích hợp với DB.
A29: DoD-4 | B29: Các thao tác cần ghi Audit Log đã được ghi.
A30: DoD-5 | B30: Chạy được trên bản deploy (Web) hoặc bản build (Mobile).
A31: DoD-6 | B31: Đã cập nhật Trạng thái trong file này và trên Trello.
A33: 5. Quy ước trạng thái (khớp cột Trello)
A34: Trạng thái | B34: Nghĩa | C34: Cột Trello tương ứng
A35: Chưa làm | B35: Đã có trong backlog, chưa bắt đầu. | C35: Backlog / Ready
A36: Đang làm | B36: Đang code. | C36: Doing
A37: Chờ review | B37: Đã mở Pull Request, chờ review/test. | C37: Review
A38: Hoàn thành | B38: Đạt đủ Definition of Done. | C38: Done
A39: Bị chặn | B39: Kẹt vì phụ thuộc hoặc câu hỏi chưa trả lời (ghi lý do ở cột Ghi chú). | C39: Blocked
A41: 6. Giả định & nguồn
A42: • | B42: Nội dung module lấy từ Report 3 (SRS) mục 3.2–3.18: 43 function + 8 chức năng chạy nền. Module Hạ tầng và Mobile lấy từ Report 2 (WBS 1.2, 7.1–7.3) và tech stack đã chốt (.NET, React + Vite, Supabase, Railway + Vercel, Replicate, Flutter).
A43: • | B43: Man-day: tổng 100 theo bảng WBS của Report 2 mục 1.1. Mỗi module gắn 1 dòng WBS, tổng từng dòng khớp R2 (xem sheet Đối chiếu WBS R2). Module hạ tầng được tính vào dòng 1.2.
A44: • | B44: Function 3.11.1 và 3.11.2 của R3 được tách mỗi cái thành 2 module để khớp đúng dòng WBS 5.1 / 5.2 / 5.3.
A45: • | B45: Một số module kỹ thuật không đứng riêng trong R3 (upload ảnh, cập nhật gần thời gian thực, thiết kế prompt, giới hạn AI, push notification) được tách ra từ các yêu cầu đã có trong R3/R2 — không thêm tính năng mới.
A46: • | B46: Lịch sprint theo mốc nộp ở R2 mục 3. Sprint S3 và S4 có cả việc Mobile chạy song song với Web.
...

Sheet Sprint
A1: KẾ HOẠCH SPRINT (2 tuần / sprint)
A2: Các cột số liệu tự tính từ sheet Product Backlog.
A4: Sprint | B4: Tuần | C4: Từ ngày | D4: Đến ngày | E4: Mốc nộp của trường | F4: Sprint goal | G4: Số module | H4: Man-day kế hoạch | I4: Trong đó Mobile | J4: Man-day đã xong | K4: % hoàn thành
A5: S1 | B5: Tuần 4–5 | C5: 46294 | D5: 46307 | E5: Report 4, Report 5 (skeleton) + Code Frame — 12/10/2026 (tuần 5) | F5: Code frame: dựng hạ tầng (repo, backend .NET, web React, CSDL 17 entity, deploy), đăng nhập & phiên, phân quyền 5 role, khung ứng dụng + Home khung, hồ sơ cá nhân, quản lý user do Admin tạo (hệ thống không có tự đăng ký — BR-14). | G5: =COUNTIF('Product Backlog'!$M$5:$M$75,A5) -> 17 | H5: =SUMIF('Product Backlog'!$M$5:$M$75,A5,'Product Backlog'!$L$5:$L$75) -> 9 | I5: =SUMPRODUCT(('Product Backlog'!$M$5:$M$75=A5)*(LEFT('Product Backlog'!$F$5:$F$75,6)="Mobile")*'Product Backlog'!$L$5:$L$75) -> 0 | J5: =SUMIFS('Product Backlog'!$L$5:$L$75,'Product Backlog'!$M$5:$M$75,A5,'Product Backlog'!$O$5:$O$75,"Hoàn thành") -> 0 | K5: =IF(H5=0,0,J5/H5) -> 0
A6: S2 | B6: Tuần 6–7 | C6: 46308 | D6: 46321 | E6: Software Package 1 (Case core) + cập nhật R3–R5 — 26/10/2026 (tuần 7) | F6: Luồng Case lõi chạy trọn: Employee gửi yêu cầu có ảnh → Officer claim, duyệt, giao KTV → Technician nhận, sửa, hoàn thành → Officer xác nhận đóng / mở lại; hủy, đánh giá; thông báo theo mốc. | G6: =COUNTIF('Product Backlog'!$M$5:$M$75,A6) -> 18 | H6: =SUMIF('Product Backlog'!$M$5:$M$75,A6,'Product Backlog'!$L$5:$L$75) -> 25 | I6: =SUMPRODUCT(('Product Backlog'!$M$5:$M$75=A6)*(LEFT('Product Backlog'!$F$5:$F$75,6)="Mobile")*'Product Backlog'!$L$5:$L$75) -> 0 | J6: =SUMIFS('Product Backlog'!$L$5:$L$75,'Product Backlog'!$M$5:$M$75,A6,'Product Backlog'!$O$5:$O$75,"Hoàn thành") -> 0 | K6: =IF(H6=0,0,J6/H6) -> 0
A7: S3 | B7: Tuần 8–9 | C7: 46322 | D7: 46335 | E7: Software Package 2 (Preventive Maintenance) — 09/11/2026 (tuần 9) | F7: Bảo trì định kỳ (kế hoạch, lịch, tự sinh work order, kiểm tra, hồ sơ); vòng đời thiết bị (nhập hàng loạt, thanh lý, QR); hoàn thiện điều phối Case (theo dõi, SLA, tìm kiếm, audit, trung tâm thông báo); Mobile bắt đầu với Employee + Technician. | G7: =COUNTIF('Product Backlog'!$M$5:$M$75,A7) -> 21 | H7: =SUMIF('Product Backlog'!$M$5:$M$75,A7,'Product Backlog'!$L$5:$L$75) -> 31 | I7: =SUMPRODUCT(('Product Backlog'!$M$5:$M$75=A7)*(LEFT('Product Backlog'!$F$5:$F$75,6)="Mobile")*'Product Backlog'!$L$5:$L$75) -> 8 | J7: =SUMIFS('Product Backlog'!$L$5:$L$75,'Product Backlog'!$M$5:$M$75,A7,'Product Backlog'!$O$5:$O$75,"Hoàn thành") -> 0 | K7: =IF(H7=0,0,J7/H7) -> 0
A8: S4 | B8: Tuần 10–11 | C8: 46336 | D8: 46349 | E8: Software Package 3 (Analytics + AI-assisted) — 23/11/2026 (tuần 11) | F8: Analytics (Manager home, KPI, hiệu suất KTV, xu hướng hỏng, xuất báo cáo) và AI-assisted support theo RBAC; Mobile Officer + push + chức năng dùng chung. Mốc nội bộ: xong mức Package 3 ngay trong tuần 10. | G8: =COUNTIF('Product Backlog'!$M$5:$M$75,A8) -> 13 | H8: =SUMIF('Product Backlog'!$M$5:$M$75,A8,'Product Backlog'!$L$5:$L$75) -> 31 | I8: =SUMPRODUCT(('Product Backlog'!$M$5:$M$75=A8)*(LEFT('Product Backlog'!$F$5:$F$75,6)="Mobile")*'Product Backlog'!$L$5:$L$75) -> 7 | J8: =SUMIFS('Product Backlog'!$L$5:$L$75,'Product Backlog'!$M$5:$M$75,A8,'Product Backlog'!$O$5:$O$75,"Hoàn thành") -> 0 | K8: =IF(H8=0,0,J8/H8) -> 0
A9: S5 | B9: Tuần 12–13 | C9: 46350 | D9: 46363 | E9: Full Software Package + System Test — 07/12/2026 (tuần 13) | F9: Mobile Manager + Administrator (đủ 5 role, Web = Mobile); system test toàn bộ Web + Mobile, sửa lỗi, kiểm tra bảo mật AI (buffer). | G9: =COUNTIF('Product Backlog'!$M$5:$M$75,A9) -> 2 | H9: =SUMIF('Product Backlog'!$M$5:$M$75,A9,'Product Backlog'!$L$5:$L$75) -> 4 | I9: =SUMPRODUCT(('Product Backlog'!$M$5:$M$75=A9)*(LEFT('Product Backlog'!$F$5:$F$75,6)="Mobile")*'Product Backlog'!$L$5:$L$75) -> 4 | J9: =SUMIFS('Product Backlog'!$L$5:$L$75,'Product Backlog'!$M$5:$M$75,A9,'Product Backlog'!$O$5:$O$75,"Hoàn thành") -> 0 | K9: =IF(H9=0,0,J9/H9) -> 0
A10: Tổng | G10: =SUM(G5:G9) -> 71 | H10: =SUM(H5:H9) -> 100 | I10: =SUM(I5:I9) -> 19 | J10: =SUM(J5:J9) -> 0 | K10: =IF(H10=0,0,J10/H10) -> 0
A12: Ghi chú: ngày sprint và mốc nộp lấy từ Report 2 mục 3 (Project Deliverables); tuần 1 bắt đầu 08/09/2026. Sprint S3–S4 có việc Mobile (Tùng) chạy song song với Web/Backend.

Sheet Product Backlog
A1: PRODUCT BACKLOG — SmartMaint
A2: Ô nền vàng (Owner, Trạng thái, Ghi chú) là ô nhóm cập nhật. Man-day theo WBS Report 2 (tổng 100). Nội dung theo Report 3 mục 3.2–3.18.
A4: STT | B4: Mã module | C4: Tên module | D4: Nhóm chức năng | E4: Mục R3 | F4: Loại | G4: Việc / tính năng cần làm | H4: Màn hình / chức năng liên quan | I4: Business rule | J4: Phụ thuộc | K4: Mục WBS (R2) | L4: Man-day | M4: Sprint | N4: Owner | O4: Trạng thái | P4: Ghi chú
A5: 1 | B5: M-01 | C5: Thiết lập repo & quy trình Git | D5: Hạ tầng dự án | E5: — | F5: Hạ tầng | G5: • Tạo cấu trúc thư mục backend/, frontend/, mobile/, docs/ trong repo SmartMaint • Nhánh main luôn chạy được; làm việc trên feature branch, merge qua Pull Request có ít nhất 1 review (R2 mục 6.2) • Gắn tag release ở mỗi mốc nộp (tuần 5, 7, 9, 11, 13) • .gitignore, .env.example liệt kê đủ biến môi trường; sửa README từ NestJS sang .NET • GitHub Actions: tự build + chạy test backend và frontend mỗi PR | H5: — | I5: — | J5: — | K5: 1.2 | L5: 0.25 | M5: S1 | O5: Chưa làm
A6: 2 | B6: M-02 | C6: Khung Backend .NET (C#) | D6: Hạ tầng dự án | E6: — | F6: Backend | G6: • Tạo solution chia theo module nghiệp vụ: Auth, User, Case, Asset, Preventive, Analytics, AI, Notification, Audit • Tách rõ controller / service / DTO; validate dữ liệu đầu vào dùng chung • Middleware xử lý lỗi chung: trả mã tham chiếu cho lỗi 500 (dùng ở ERR-03) • Cấu hình JWT, Swagger (tài liệu API), logging | H6: — | I6: — | J6: M-01 | K6: 1.2 | L6: 0.5 | M6: S1 | O6: Chưa làm
A7: 3 | B7: M-03 | C7: Khung Web React + Vite | D7: Hạ tầng dự án | E7: — | F7: Web | G7: • Cấu trúc thư mục features/ – shared/ – lib/ • Routing theo role; route guard chặn trang không có quyền • API client + interceptor gắn token, bắt lỗi 401 để mở AUTH-05 • Design token (màu trạng thái, font) theo HTML prototype; khung song ngữ Anh/Việt | H7: — | I7: — | J7: M-01 | K7: 1.2 | L7: 0.5 | M7: S1 | O7: Chưa làm
A8: 4 | B8: M-04 | C8: Cơ sở dữ liệu & dữ liệu mẫu (17 entity) | D8: Hạ tầng dự án | E8: 3.1.5 ERD | F8: Backend | G8: • Tạo schema PostgreSQL trên Supabase theo ERD 17 entity: Building, Floor, Room, AssetCategory, Asset, User, Case, CaseComment, CaseAttachment, PreventivePlan, InspectionRecord, AuditLog, AIConversation, Notification, IssueType, RootCause, SystemSetting • Quan hệ PreventivePlan nhiều–nhiều Asset (bảng trung gian) • Migration (EF Core) để dựng lại DB được bất cứ lúc nào • Seed dữ liệu mẫu: tòa nhà/tầng/phòng/thiết bị, user đủ 5 role, danh mục, cài đặt SLA mặc định | H8: — | I8: — | J8: M-02 | K8: 1.2 | L8: 0.75 | M8: S1 | O8: Chưa làm
A9: 5 | B9: M-05 | C9: Triển khai Railway + Vercel | D9: Hạ tầng dự án | E9: 4.1 | F9: Hạ tầng | G9: • Deploy backend .NET lên Railway, web React lên Vercel • Cấu hình biến môi trường, kết nối Supabase, CORS • Có link demo online cho code frame; tự deploy lại khi merge vào main | H9: — | I9: — | J9: M-02, M-03, M-04 | K9: 1.2 | L9: 0.25 | M9: S1 | O9: Chưa làm
A10: 6 | B10: M-06 | C10: Phân quyền RBAC 5 role | D10: Hạ tầng dự án | E10: 3.1.3 | F10: Backend | G10: • Policy/attribute phân quyền dùng chung, không kiểm tra tay từng chỗ • Phạm vi dữ liệu theo role: của mình / được giao / tất cả / không có • Administrator không xem được nội dung case ở bất kỳ đâu (BR-11) • Mọi lần bị chặn (403) đều ghi Audit Log • Test tự động bảng Screen Authorization (3.1.3) cho 5 role | H10: 3.1.3 Screen Authorization | I10: BR-11, BR-16 | J10: M-02, M-04 | K10: 1.2 | L10: 0.75 | M10: S1 | O10: Chưa làm
A11: 7 | B11: M-07 | C11: Đăng nhập | D11: Đăng nhập & khôi phục tài khoản | E11: 3.2.1 | F11: Web + Backend | G11: • Form email + mật khẩu; báo lỗi trường trống ngay ở client • Sai thông tin: chỉ báo chung "Email or password is incorrect" • Sai 5 lần → khóa 15 phút; tài khoản bị vô hiệu → AUTH-06 • Nhớ link mở trước khi đăng nhập (thông báo, QR) và mở lại sau khi đăng nhập • Chuyển về Home đúng role, hoặc AUTH-04 nếu là mật khẩu tạm • Không có tự đăng ký — tài khoản chỉ do Admin tạo (BR-14); ghi Audit Log mọi lần đăng nhập | H11: AUTH-01 | I11: BR-14, BR-16, BR-18 | J11: M-06, M-03 | K11: 1.1 | L11: 1 | M11: S1 | O11: Chưa làm
A12: 8 | B12: M-08 | C12: Quên & đặt lại mật khẩu | D12: Đăng nhập & khôi phục tài khoản | E12: 3.2.2 | F12: Web + Backend | G12: • AUTH-02: nhập email, luôn hiện cùng một thông báo (không lộ email nào có tài khoản) • Gửi email chứa link đặt lại (tích hợp dịch vụ gửi email, dùng lại cho thông báo sau này) • Link hiệu lực 30 phút, dùng 1 lần; gửi lại tối đa 1 lần/60 giây • AUTH-03: checklist mật khẩu trực tiếp (≥ 8 ký tự, có hoa, thường, số; khác mật khẩu cũ) • Lưu xong: kết thúc các phiên khác + gửi email xác nhận; ghi Audit Log | H12: AUTH-02, AUTH-03 | I12: BR-16, BR-18 | J12: M-07 | K12: 1.1 | L12: 0.5 | M12: S1 | O12: Chưa làm
A13: 9 | B13: M-09 | C13: Đổi mật khẩu lần đầu & quản lý phiên | D13: Đăng nhập & khôi phục tài khoản | E13: 3.2.3 | F13: Web + Backend | G13: • AUTH-04: chặn mọi trang cho tới khi đổi mật khẩu tạm (cùng quy tắc AUTH-03) • Phiên 8 tiếng (chỉnh được ở ADM-07); cảnh báo trước 5 phút • AUTH-05: lớp phủ hết phiên, đăng nhập lại quay về đúng trang, giữ dữ liệu đang gõ • AUTH-06: tài khoản bị vô hiệu; đăng xuất ngay nếu Admin vô hiệu khi đang dùng | H13: AUTH-04, AUTH-05, AUTH-06 | I13: BR-18 | J13: M-07 | K13: 1.1 | L13: 0.5 | M13: S1 | O13: Chưa làm
A14: 10 | B14: M-10 | C14: Khung ứng dụng & điều hướng | D14: Khung ứng dụng & trang hệ thống | E14: 3.3.1 | F14: Web | G14: • Menu trái chỉ gồm các màn role được mở; top bar có ô tìm kiếm, chuông thông báo (hiện số tới 99, sau đó "99+"), menu avatar • Nút AI nổi góc dưới phải (giao diện chat làm ở module AI Assistant) • Dưới 1024 px menu thu thành nút hamburger, bảng cuộn ngang • Menu Administrator không có mục liên quan case (BR-11) • Trang Home khung cho 5 role (nội dung hoàn thiện ở các sprint sau) • Đăng xuất: chỉ hỏi xác nhận khi form còn thay đổi chưa lưu (DLG-19) | H14: COM-01 | I14: BR-11 | J14: M-03, M-06 | K14: 1.2 | L14: 0.5 | M14: S1 | O14: Chưa làm
A15: 11 | B15: M-11 | C15: Trang lỗi & mất kết nối | D15: Khung ứng dụng & trang hệ thống | E15: 3.3.2 | F15: Web | G15: • ERR-01 Không có quyền (403) — không xác nhận bản ghi có tồn tại hay không • ERR-02 Không tìm thấy (404); ERR-03 Lỗi máy chủ (500) kèm mã tham chiếu • Lỗi một phần trang: "Could not load. Retry" tại chỗ • ERR-04 Mất mạng: thanh báo trên cùng, tắt nút Submit, tự tiếp tục upload khi có mạng lại • Luôn có nút về Home của role | H15: ERR-01 → ERR-04 | I15: BR-16 | J15: M-10 | K15: 1.2 | L15: 0.25 | M15: S1 | O15: Chưa làm
A16: 12 | B16: M-12 | C16: Tham chiếu vai trò & quyền | D16: Quản trị người dùng & truy cập | E16: 3.12.4 | F16: Web | G16: • Trang chỉ đọc cho Admin: bảng năng lực × 5 role (Yes / View only / Own only / No) • Sinh từ chính bộ quy tắc phân quyền đang chạy nên không bị lệch • Mỗi role có 1 dòng ghi chú AI được trả lời trong phạm vi nào | H16: ADM-05 | I16: — | J16: M-06 | K16: 1.2 | L16: 0.25 | M16: S1 | O16: Chưa làm
... A75: 71 | B75: M-71 | C75: Mobile: chức năng Administrator | D75: Ứng dụng Mobile (Flutter) | E75: 3.12, 3.13 (Mobile) | F75: Mobile | G75: • Trang chủ Admin, danh sách/chi tiết/tạo/sửa user, thao tác tài khoản • Danh mục bảo trì, cài đặt SLA, xem Audit Log, cây cơ sở vật chất và thiết bị • Không có nội dung case (BR-11) | H75: ADM-01 → ADM-08, AST-01 → AST-05 | I75: BR-11 | J75: M-54, M-16, M-42 | K75: 7.2 | L75: 2 | M75: S5 | O75: Chưa làm
K76: Tổng | L76: =SUM(L5:L75) -> 100
A77: Nguồn man-day: Report 2, mục 1.1 Scope & Estimation (tổng 100 man-day, Leader chốt 28/09/2026).

Sheet Đối chiếu WBS R2
A1: ĐỐI CHIẾU MAN-DAY VỚI WBS REPORT 2
A2: Cột "Man-day R2" nhập tay theo Report 2 mục 1.1 (chữ xanh). Các cột còn lại tự tính từ Product Backlog; Chênh lệch = 0 nghĩa là khớp.
A4: Mục WBS | B4: Hạng mục (Report 2) | C4: Man-day R2 | D4: Man-day Product Backlog | E4: Chênh lệch | F4: Số module
A5: 1 | B5: Authentication & User Management | C5: =SUM(C6:C8) -> 8 | D5: =SUM(D6:D8) -> 8 | E5: =D5-C5 -> 0 | F5: =SUM(F6:F8) -> 16
A6: 1.1 | B6: Login / Registration (Web + Mobile) | C6: 2 | D6: =SUMIF('Product Backlog'!$K$5:$K$75,A6,'Product Backlog'!$L$5:$L$75) -> 2 | E6: =D6-C6 -> 0 | F6: =COUNTIF('Product Backlog'!$K$5:$K$75,A6) -> 3
A7: 1.2 | B7: Role-Based Access Control (5 roles) | C7: 4 | D7: =SUMIF('Product Backlog'!$K$5:$K$75,A7,'Product Backlog'!$L$5:$L$75) -> 4 | E7: =D7-C7 -> 0 | F7: =COUNTIF('Product Backlog'!$K$5:$K$75,A7) -> 9
A8: 1.3 | B8: User profile management | C8: 2 | D8: =SUMIF('Product Backlog'!$K$5:$K$75,A8,'Product Backlog'!$L$5:$L$75) -> 2 | E8: =D8-C8 -> 0 | F8: =COUNTIF('Product Backlog'!$K$5:$K$75,A8) -> 4
A9: 2 | B9: Asset & Facility Management | C9: =SUM(C10:C12) -> 5 | D9: =SUM(D10:D12) -> 5 | E9: =D9-C9 -> 0 | F9: =SUM(F10:F12) -> 6
A10: 2.1 | B10: Building / Floor / Room CRUD | C10: 2 | D10: =SUMIF('Product Backlog'!$K$5:$K$75,A10,'Product Backlog'!$L$5:$L$75) -> 2 | E10: =D10-C10 -> 0 | F10: =COUNTIF('Product Backlog'!$K$5:$K$75,A10) -> 2
A11: 2.2 | B11: Asset CRUD + maintenance history | C11: 2 | D11: =SUMIF('Product Backlog'!$K$5:$K$75,A11,'Product Backlog'!$L$5:$L$75) -> 2 | E11: =D11-C11 -> 0 | F11: =COUNTIF('Product Backlog'!$K$5:$K$75,A11) -> 3
A12: 2.3 | B12: Assign asset to a Maintenance Case | C12: 1 | D12: =SUMIF('Product Backlog'!$K$5:$K$75,A12,'Product Backlog'!$L$5:$L$75) -> 1 | E12: =D12-C12 -> 0 | F12: =COUNTIF('Product Backlog'!$K$5:$K$75,A12) -> 1
A13: 3 | B13: Maintenance Case Management (core) | C13: =SUM(C14:C19) -> 33 | D13: =SUM(D14:D19) -> 33 | E13: =D13-C13 -> 0 | F13: =SUM(F14:F19) -> 25
A14: 3.1 | B14: Case creation with photo upload (Employee) | C14: 5 | D14: =SUMIF('Product Backlog'!$K$5:$K$75,A14,'Product Backlog'!$L$5:$L$75) -> 5 | E14: =D14-C14 -> 0 | F14: =COUNTIF('Product Backlog'!$K$5:$K$75,A14) -> 5
A15: 3.2 | B15: Approval workflow: Approve / Reject / Need Info | C15: 6 | D15: =SUMIF('Product Backlog'!$K$5:$K$75,A15,'Product Backlog'!$L$5:$L$75) -> 6 | E15: =D15-C15 -> 0 | F15: =COUNTIF('Product Backlog'!$K$5:$K$75,A15) -> 4
A16: 3.3 | B16: Work Order assignment to Technician | C16: 5 | D16: =SUMIF('Product Backlog'!$K$5:$K$75,A16,'Product Backlog'!$L$5:$L$75) -> 5 | E16: =D16-C16 -> 0 | F16: =COUNTIF('Product Backlog'!$K$5:$K$75,A16) -> 5
A17: 3.4 | B17: Technician accept/update + evidence upload | C17: 6 | D17: =SUMIF('Product Backlog'!$K$5:$K$75,A17,'Product Backlog'!$L$5:$L$75) -> 6 | E17: =D17-C17 -> 0 | F17: =COUNTIF('Product Backlog'!$K$5:$K$75,A17) -> 4
A18: 3.5 | B18: Verify / Close / Reopen workflow | C18: 5 | D18: =SUMIF('Product Backlog'!$K$5:$K$75,A18,'Product Backlog'!$L$5:$L$75) -> 5 | E18: =D18-C18 -> 0 | F18: =COUNTIF('Product Backlog'!$K$5:$K$75,A18) -> 4
A19: 3.6 | B19: Notification at case-lifecycle milestones | C19: 6 | D19: =SUMIF('Product Backlog'!$K$5:$K$75,A19,'Product Backlog'!$L$5:$L$75) -> 6 | E19: =D19-C19 -> 0 | F19: =COUNTIF('Product Backlog'!$K$5:$K$75,A19) -> 3
A20: 4 | B20: Preventive Maintenance | C20: =SUM(C21:C23) -> 11 | D20: =SUM(D21:D23) -> 11 | E20: =D20-C20 -> 0 | F20: =SUM(F21:F23) -> 6
A21: 4.1 | B21: Recurring maintenance schedule setup | C21: 5 | D21: =SUMIF('Product Backlog'!$K$5:$K$75,A21,'Product Backlog'!$L$5:$L$75) -> 5 | E21: =D21-C21 -> 0 | F21: =COUNTIF('Product Backlog'!$K$5:$K$75,A21) -> 2
A22: 4.2 | B22: Due-date reminders for Officers | C22: 3 | D22: =SUMIF('Product Backlog'!$K$5:$K$75,A22,'Product Backlog'!$L$5:$L$75) -> 3 | E22: =D22-C22 -> 0 | F22: =COUNTIF('Product Backlog'!$K$5:$K$75,A22) -> 1
A23: 4.3 | B23: Preventive maintenance history log | C23: 3 | D23: =SUMIF('Product Backlog'!$K$5:$K$75,A23,'Product Backlog'!$L$5:$L$75) -> 3 | E23: =D23-C23 -> 0 | F23: =COUNTIF('Product Backlog'!$K$5:$K$75,A23) -> 3
A24: 5 | B24: Analytics & Decision Support | C24: =SUM(C25:C27) -> 16 | D24: =SUM(D25:D27) -> 16 | E24: =D24-C24 -> 0 | F24: =SUM(F25:F27) -> 5
A25: 5.1 | B25: KPI dashboard (case volume, resolution time) | C25: 6 | D25: =SUMIF('Product Backlog'!$K$5:$K$75,A25,'Product Backlog'!$L$5:$L$75) -> 6 | E25: =D25-C25 -> 0 | F25: =COUNTIF('Product Backlog'!$K$5:$K$75,A25) -> 2
A26: 5.2 | B26: Technician performance report | C26: 5 | D26: =SUMIF('Product Backlog'!$K$5:$K$75,A26,'Product Backlog'!$L$5:$L$75) -> 5 | E26: =D26-C26 -> 0 | F26: =COUNTIF('Product Backlog'!$K$5:$K$75,A26) -> 2
A27: 5.3 | B27: Recurring asset-failure report | C27: 5 | D27: =SUMIF('Product Backlog'!$K$5:$K$75,A27,'Product Backlog'!$L$5:$L$75) -> 5 | E27: =D27-C27 -> 0 | F27: =COUNTIF('Product Backlog'!$K$5:$K$75,A27) -> 1
A28: 6 | B28: AI-assisted Support | C28: =SUM(C29:C30) -> 8 | D28: =SUM(D29:D30) -> 8 | E28: =D28-C28 -> 0 | F28: =SUM(F29:F30) -> 5
A29: 6.1 | B29: Third-party AI API integration | C29: 5 | D29: =SUMIF('Product Backlog'!$K$5:$K$75,A29,'Product Backlog'!$L$5:$L$75) -> 5 | E29: =D29-C29 -> 0 | F29: =COUNTIF('Product Backlog'!$K$5:$K$75,A29) -> 3
A30: 6.2 | B30: FAQ / troubleshooting prompt design | C30: 3 | D30: =SUMIF('Product Backlog'!$K$5:$K$75,A30,'Product Backlog'!$L$5:$L$75) -> 3 | E30: =D30-C30 -> 0 | F30: =COUNTIF('Product Backlog'!$K$5:$K$75,A30) -> 2
A31: 7 | B31: Mobile Application (Flutter) | C31: =SUM(C32:C34) -> 19 | D31: =SUM(D32:D34) -> 19 | E31: =D31-C31 -> 0 | F31: =SUM(F32:F34) -> 8
A32: 7.1 | B32: Employee & Officer screens: submit, track, approve, assign, verify | C32: 7 | D32: =SUMIF('Product Backlog'!$K$5:$K$75,A32,'Product Backlog'!$L$5:$L$75) -> 7 | E32: =D32-C32 -> 0 | F32: =COUNTIF('Product Backlog'!$K$5:$K$75,A32) -> 2
A33: 7.2 | B33: Technician, Manager & Admin screens: work orders, dashboards, administration | C33: 7 | D33: =SUMIF('Product Backlog'!$K$5:$K$75,A33,'Product Backlog'!$L$5:$L$75) -> 7 | E33: =D33-C33 -> 0 | F33: =COUNTIF('Product Backlog'!$K$5:$K$75,A33) -> 3
A34: 7.3 | B34: Mobile auth & push notifications | C34: 5 | D34: =SUMIF('Product Backlog'!$K$5:$K$75,A34,'Product Backlog'!$L$5:$L$75) -> 5 | E34: =D34-C34 -> 0 | F34: =COUNTIF('Product Backlog'!$K$5:$K$75,A34) -> 3
B35: TỔNG | C35: =C5+C9+C13+C20+C24+C28+C31 -> 100 | D35: =D5+D9+D13+D20+D24+D28+D31 -> 100 | E35: =D35-C35 -> 0 | F35: =F5+F9+F13+F20+F24+F28+F31 -> 71
